<?xml version="1.0" ?>
<!-- =================================================================================== -->
<!-- |    This document was autogenerated by xacro from dual_robot_description.xacro   | -->
<!-- |    EDITING THIS FILE BY HAND IS NOT RECOMMENDED                                 | -->
<!-- =================================================================================== -->
<robot name="kuka_meca">
  <link name="meca_base_link">
    <visual>
      <origin rpy="0 0 0" xyz="0 0 0"/>
      <geometry>
        <mesh filename="package://example-robot-data/robots/dual_robot_description/meshes/visual/meca_500_r3_base.dae"/>
      </geometry>
    </visual>
    <collision>
      <origin rpy="0 0 0" xyz="0 0 0"/>
      <geometry>
        <mesh filename="package://example-robot-data/robots/dual_robot_description/meshes/collision/meca_500_r3_base_collision.stl"/>
      </geometry>
    </collision>
  </link>
  <!-- Joint 1 -->
  <link name="meca_axis_1_link">
    <visual>
      <origin rpy="0 0 0" xyz="0 0 0"/>
      <geometry>
        <mesh filename="package://example-robot-data/robots/dual_robot_description/meshes/visual/meca_500_r3_j1.dae"/>
      </geometry>
    </visual>
    <collision>
      <origin rpy="0 0 0" xyz="0 0 0"/>
      <geometry>
        <mesh filename="package://example-robot-data/robots/dual_robot_description/meshes/collision/meca_500_r3_j1_collision.stl"/>
      </geometry>
    </collision>
    <inertial>
      <mass value="1.0"/>
      <origin rpy="0 0 0" xyz="0 0 0.0"/>
      <inertia ixx="1.0" ixy="1.0" ixz="0" iyy="0.0" iyz="1.0" izz="0.0"/>
    </inertial>
  </link>
  <joint name="meca_axis_1_joint" type="revolute">
    <origin rpy="0 0 0" xyz="0.012498 0 0.091"/>
    <parent link="meca_base_link"/>
    <child link="meca_axis_1_link"/>
    <axis xyz="0 0 1"/>
    <limit effort="10.0" lower="-3.05433" upper="3.05433" velocity="2.61799"/>
  </joint>
  <!-- Joint 2 -->
  <link name="meca_axis_2_link">
    <visual>
      <origin rpy="0 0 0" xyz="0 0 0"/>
      <geometry>
        <mesh filename="package://example-robot-data/robots/dual_robot_description/meshes/visual/meca_500_r3_j2.dae"/>
      </geometry>
    </visual>
    <collision>
      <origin rpy="0 0 0" xyz="0 0 0"/>
      <geometry>
        <mesh filename="package://example-robot-data/robots/dual_robot_description/meshes/collision/meca_500_r3_j2_collision.stl"/>
      </geometry>
    </collision>
    <inertial>
      <mass value="1.0"/>
      <origin rpy="0 0 0" xyz="0 0 0.0"/>
      <inertia ixx="1.0" ixy="1.0" ixz="0" iyy="0.0" iyz="1.0" izz="0.0"/>
    </inertial>
  </link>
  <joint name="meca_axis_2_joint" type="revolute">
    <origin rpy="0 0 0" xyz="0 0 0.044"/>
    <parent link="meca_axis_1_link"/>
    <child link="meca_axis_2_link"/>
    <axis xyz="0 1 0"/>
    <limit effort="10.0" lower="-1.22173048" upper="1.5708" velocity="2.61799"/>
  </joint>
  <!-- Joint 3 -->
  <link name="meca_axis_3_link">
    <visual>
      <origin rpy="0 0 0" xyz="0 0 0"/>
      <geometry>
        <mesh filename="package://example-robot-data/robots/dual_robot_description/meshes/visual/meca_500_r3_j3.dae"/>
      </geometry>
    </visual>
    <collision>
      <origin rpy="0 0 0" xyz="0 0 0"/>
      <geometry>
        <mesh filename="package://example-robot-data/robots/dual_robot_description/meshes/collision/meca_500_r3_j3_collision.stl"/>
      </geometry>
    </collision>
    <inertial>
      <mass value="1.0"/>
      <origin rpy="0 0 0" xyz="0 0 0.0"/>
      <inertia ixx="1.0" ixy="1.0" ixz="0" iyy="0.0" iyz="1.0" izz="0.0"/>
    </inertial>
  </link>
  <joint name="meca_axis_3_joint" type="revolute">
    <origin rpy="0 0 0" xyz="0 0 0.135"/>
    <parent link="meca_axis_2_link"/>
    <child link="meca_axis_3_link"/>
    <axis xyz="0 1 0"/>
    <limit effort="10.0" lower="-2.35619" upper="1.22173048" velocity="3.14159"/>
  </joint>
  <!-- Joint 4 -->
  <link name="meca_axis_4_link">
    <visual>
      <origin rpy="0 0 0" xyz="0 0 0"/>
      <geometry>
        <mesh filename="package://example-robot-data/robots/dual_robot_description/meshes/visual/meca_500_r3_j4.dae"/>
      </geometry>
    </visual>
    <collision>
      <origin rpy="0 0 0" xyz="0 0 0"/>
      <geometry>
        <mesh filename="package://example-robot-data/robots/dual_robot_description/meshes/collision/meca_500_r3_j4_collision.stl"/>
      </geometry>
    </collision>
    <inertial>
      <mass value="1.0"/>
      <origin rpy="0 0 0" xyz="0 0 0.0"/>
      <inertia ixx="1.0" ixy="1.0" ixz="0" iyy="0.0" iyz="1.0" izz="0.0"/>
    </inertial>
  </link>
  <joint name="meca_axis_4_joint" type="revolute">
    <origin rpy="0 0 0" xyz="0 0 0.038"/>
    <parent link="meca_axis_3_link"/>
    <child link="meca_axis_4_link"/>
    <axis xyz="1 0 0"/>
    <limit effort="10.0" lower="-2.96706" upper="2.96706" velocity="5.23599"/>
  </joint>
  <!-- Joint 5 -->
  <link name="meca_axis_5_link">
    <visual>
      <origin rpy="0 0 0" xyz="0 0 0"/>
      <geometry>
        <mesh filename="package://example-robot-data/robots/dual_robot_description/meshes/visual/meca_500_r3_j5.dae"/>
      </geometry>
    </visual>
    <collision>
      <origin rpy="0 0 0" xyz="0 0 0"/>
      <geometry>
        <mesh filename="package://example-robot-data/robots/dual_robot_description/meshes/collision/meca_500_r3_j5_collision.stl"/>
      </geometry>
    </collision>
    <inertial>
      <mass value="1.0"/>
      <origin rpy="0 0 0" xyz="0 0 0.0"/>
      <inertia ixx="1.0" ixy="1.0" ixz="0" iyy="0.0" iyz="1.0" izz="0.0"/>
    </inertial>
  </link>
  <joint name="meca_axis_5_joint" type="revolute">
    <origin rpy="0 0 0" xyz="0.12 0 0"/>
    <parent link="meca_axis_4_link"/>
    <child link="meca_axis_5_link"/>
    <axis xyz="0 1 0"/>
    <limit effort="10.0" lower="-2.00713" upper="2.00713" velocity="5.23599"/>
  </joint>
  <!-- Joint 6 -->
  <link name="meca_axis_6_link">
    <visual>
      <origin rpy="0 0 0" xyz="0 0 0"/>
      <geometry>
        <mesh filename="package://example-robot-data/robots/dual_robot_description/meshes/visual/meca_500_r3_j6.dae"/>
      </geometry>
    </visual>
    <collision>
      <origin rpy="0 0 0" xyz="0 0 0"/>
      <geometry>
        <mesh filename="package://example-robot-data/robots/dual_robot_description/meshes/collision/meca_500_r3_j6_collision.stl"/>
      </geometry>
    </collision>
    <inertial>
      <mass value="1.0"/>
      <origin rpy="0 0 0" xyz="0 0 0.0"/>
      <inertia ixx="1.0" ixy="1.0" ixz="0" iyy="0.0" iyz="1.0" izz="0.0"/>
    </inertial>
  </link>
  <joint name="meca_axis_6_joint" type="revolute">
    <origin rpy="0 0 0" xyz="0.07 0 0"/>
    <parent link="meca_axis_5_link"/>
    <child link="meca_axis_6_link"/>
    <axis xyz="1 0 0"/>
    <limit effort="10.0" lower="-3.14159" upper="3.14159" velocity="8.72665"/>
  </joint>
  <link name="tool_meca">
    <visual>
      <origin rpy="0 0 0" xyz="0 0 0"/>
      <geometry>
        <mesh filename="package://example-robot-data/robots/dual_robot_description/meshes/visual/GRIPPER.stl"/>
      </geometry>
    </visual>
    <collision>
      <origin rpy="0 0 0" xyz="0 0 0"/>
      <geometry>
        <mesh filename="package://example-robot-data/robots/dual_robot_description/meshes/collision/GRIPPER.stl"/>
      </geometry>
    </collision>
    <inertial>
      <mass value="1.0"/>
      <origin rpy="0 0 0" xyz="0 0 0.0"/>
      <inertia ixx="1.0" ixy="1.0" ixz="0" iyy="0.0" iyz="1.0" izz="0.0"/>
    </inertial>
  </link>
  <joint name="meca_axis_6_joint-tool_meca" type="fixed">
    <parent link="meca_axis_6_link"/>
    <child link="tool_meca"/>
    <origin rpy="0 1.5707963267948966 0" xyz="0.075 0 0"/>
  </joint>
  <link name="tcp_meca"/>
  <joint name="tool_meca-tcp_meca" type="fixed">
    <parent link="tool_meca"/>
    <child link="tcp_meca"/>
    <origin rpy="0 0 0" xyz="0 0.002 0"/>
  </joint>
  <!-- colours based on RAL values given in "FAQ - Colours of robot and robot
       controller", version "KUKA.Tifs | 2010-01-21 |YM| DefaultColorsRobotAndController.doc",
       downloaded 2015-07-18 from
       http://www.kuka.be/main/cservice/faqs/hardware/DefaultColorsRobotAndController.pdf

       all RAL colours converted using http://www.visual-graphics.de/en/customer-care/ral-colours
  -->
  <link name="base_link">
    <!-- <xacro:default_inertial mass="1"/> -->
    <visual>
      <origin rpy="0 0 0" xyz="0 0 0"/>
      <geometry>
        <mesh filename="package://example-robot-data/robots/dual_robot_description/meshes/visual/base_link.stl"/>
      </geometry>
      <material name="">
        <color rgba="0.5058823529411764 0.47058823529411764 0.38823529411764707 1.0"/>
      </material>
    </visual>
    <collision>
      <origin rpy="0 0 0" xyz="0 0 0"/>
      <geometry>
        <mesh filename="package://example-robot-data/robots/dual_robot_description/meshes/collision/base_link.stl"/>
      </geometry>
    </collision>
  </link>
  <link name="link_1">
    <inertial>
      <mass value="1"/>
      <inertia ixx="1.0" ixy="0.0" ixz="0.0" iyy="1.0" iyz="0.0" izz="1.0"/>
    </inertial>
    <visual>
      <origin rpy="0 0 0" xyz="0 0 0"/>
      <geometry>
        <mesh filename="package://example-robot-data/robots/dual_robot_description/meshes/visual/link_1.stl"/>
      </geometry>
      <material name="">
        <color rgba="0.9450980392156862 0.9254901960784314 1.0 1.0"/>
      </material>
    </visual>
    <collision>
      <origin rpy="0 0 0" xyz="0 0 0"/>
      <geometry>
        <mesh filename="package://example-robot-data/robots/dual_robot_description/meshes/collision/link_1.stl"/>
      </geometry>
    </collision>
  </link>
  <link name="link_2">
    <inertial>
      <mass value="1"/>
      <inertia ixx="1.0" ixy="0.0" ixz="0.0" iyy="1.0" iyz="0.0" izz="1.0"/>
    </inertial>
    <visual>
      <origin rpy="0 0 0" xyz="0 0 -0.33"/>
      <geometry>
        <mesh filename="package://example-robot-data/robots/dual_robot_description/meshes/visual/link_2.stl"/>
      </geometry>
      <material name="">
        <color rgba="0.9450980392156862 0.9254901960784314 1.0 1.0"/>
      </material>
    </visual>
    <collision>
      <origin rpy="0 0 0" xyz="0 0 -0.33"/>
      <geometry>
        <mesh filename="package://example-robot-data/robots/dual_robot_description/meshes/collision/link_2.stl"/>
      </geometry>
    </collision>
  </link>
  <link name="link_3">
    <inertial>
      <mass value="1"/>
      <inertia ixx="1.0" ixy="0.0" ixz="0.0" iyy="1.0" iyz="0.0" izz="1.0"/>
    </inertial>
    <visual>
      <origin rpy="0 0 0" xyz="0 0 -0.62"/>
      <geometry>
        <mesh filename="package://example-robot-data/robots/dual_robot_description/meshes/visual/link_3.stl"/>
      </geometry>
      <material name="">
        <color rgba="0.9450980392156862 0.9254901960784314 1.0 1.0"/>
      </material>
    </visual>
    <collision>
      <origin rpy="0 0 0" xyz="0 0 -0.62"/>
      <geometry>
        <mesh filename="package://example-robot-data/robots/dual_robot_description/meshes/collision/link_3.stl"/>
      </geometry>
    </collision>
  </link>
  <link name="link_4">
    <inertial>
      <mass value="1"/>
      <inertia ixx="1.0" ixy="0.0" ixz="0.0" iyy="1.0" iyz="0.0" izz="1.0"/>
    </inertial>
    <visual>
      <origin rpy="0 0 0" xyz="0 0 -0.64"/>
      <geometry>
        <mesh filename="package://example-robot-data/robots/dual_robot_description/meshes/visual/link_4.stl"/>
      </geometry>
      <material name="">
        <color rgba="0.9450980392156862 0.9254901960784314 1.0 1.0"/>
      </material>
    </visual>
    <collision>
      <origin rpy="0 0 0" xyz="0 0 -0.64"/>
      <geometry>
        <mesh filename="package://example-robot-data/robots/dual_robot_description/meshes/collision/link_4.stl"/>
      </geometry>
    </collision>
  </link>
  <link name="link_5">
    <inertial>
      <mass value="1"/>
      <inertia ixx="1.0" ixy="0.0" ixz="0.0" iyy="1.0" iyz="0.0" izz="1.0"/>
    </inertial>
    <visual>
      <origin rpy="0 0 0" xyz="-0.31 0 -0.64"/>
      <geometry>
        <mesh filename="package://example-robot-data/robots/dual_robot_description/meshes/visual/link_5.stl"/>
      </geometry>
      <material name="">
        <color rgba="0.9450980392156862 0.9254901960784314 1.0 1.0"/>
      </material>
    </visual>
    <collision>
      <origin rpy="0 0 0" xyz="-0.31 0 -0.64"/>
      <geometry>
        <mesh filename="package://example-robot-data/robots/dual_robot_description/meshes/collision/link_5.stl"/>
      </geometry>
    </collision>
  </link>
  <link name="link_6">
    <inertial>
      <mass value="1"/>
      <inertia ixx="1.0" ixy="0.0" ixz="0.0" iyy="1.0" iyz="0.0" izz="1.0"/>
    </inertial>
    <visual>
      <origin rpy="0 0 0" xyz="-0.31 0 -0.64"/>
      <geometry>
        <mesh filename="package://example-robot-data/robots/dual_robot_description/meshes/visual/link_6.stl"/>
      </geometry>
      <material name="">
        <color rgba="0.5058823529411764 0.47058823529411764 0.38823529411764707 1.0"/>
      </material>
    </visual>
    <collision>
      <origin rpy="0 0 0" xyz="-0.31 0 -0.64"/>
      <geometry>
        <mesh filename="package://example-robot-data/robots/dual_robot_description/meshes/collision/link_6.stl"/>
      </geometry>
    </collision>
  </link>
  <!-- This frame corresponds to the $FLANGE coordinate system in KUKA KRC controllers. -->
  <!-- <link name="${prefix}tool0" > -->
  <!-- This frame corresponds to the $FLANGE coordinate system in KUKA KRC controllers. -->
  <link name="tool0">
    <inertial>
      <mass value="1"/>
      <inertia ixx="1.0" ixy="0.0" ixz="0.0" iyy="1.0" iyz="0.0" izz="1.0"/>
    </inertial>
    <visual>
      <origin rpy="0 3.141592653589793 0" xyz="0 0 0"/>
      <geometry>
        <mesh filename="package://example-robot-data/robots/dual_robot_description/meshes/visual/gripper_zimmer.stl"/>
      </geometry>
      <material name="grey">
        <color rgba="0.6666666666666666 0.6666666666666666 0.6666666666666666 1"/>
      </material>
    </visual>
    <collision>
      <origin rpy="0 3.141592653589793 0" xyz="0 0 0"/>
      <geometry>
        <mesh filename="package://example-robot-data/robots/dual_robot_description/meshes/collision/gripper_zimmer.stl"/>
      </geometry>
    </collision>
  </link>
  <link name="tcp_kuka"/>
  <joint name="joint_a1" type="revolute">
    <origin rpy="0 0 0" xyz="0 0 0.0"/>
    <!--330-->
    <parent link="base_link"/>
    <child link="link_1"/>
    <axis xyz="0 0 -1"/>
    <limit effort="0" lower="-2.9670597283903604" upper="2.9670597283903604" velocity="9.250245035569947"/>
  </joint>
  <joint name="joint_a2" type="revolute">
    <origin rpy="0 1.571 0" xyz="0.0 0.0 0.33"/>
    <parent link="link_1"/>
    <child link="link_2"/>
    <axis xyz="0 1 0"/>
    <limit effort="0" lower="-2.9670597283903604" upper="0.8726646259971648" velocity="9.232791743050003"/>
  </joint>
  <joint name="joint_a3" type="revolute">
    <origin rpy="0 -1.5707963267948966 0" xyz="0.0 0 0.29"/>
    <parent link="link_2"/>
    <child link="link_3"/>
    <axis xyz="0 1 0"/>
    <limit effort="0" lower="-1.9198621771937625" upper="2.705260340591211" velocity="9.389871375729493"/>
  </joint>
  <joint name="joint_a4" type="revolute">
    <origin rpy="0 0 0" xyz="0 0 0.02"/>
    <parent link="link_3"/>
    <child link="link_4"/>
    <axis xyz="-1 0 0"/>
    <limit effort="0" lower="-3.0543261909900767" upper="3.0543261909900767" velocity="10.471975511965978"/>
  </joint>
  <joint name="joint_a5" type="revolute">
    <origin rpy="0 0 0" xyz="0.310 0 0"/>
    <parent link="link_4"/>
    <child link="link_5"/>
    <axis xyz="0 1 0"/>
    <limit effort="0" lower="-2.0943951023931953" upper="2.0943951023931953" velocity="10.471975511965978"/>
  </joint>
  <joint name="joint_a6" type="revolute">
    <origin rpy="0 0 0" xyz="0.0 0 0"/>
    <parent link="link_5"/>
    <child link="link_6"/>
    <axis xyz="-1 0 0"/>
    <limit effort="0" lower="-6.1086523819801535" upper="6.1086523819801535" velocity="13.962634015954636"/>
  </joint>
  <joint name="joint_a6-tool0" type="fixed">
    <parent link="link_6"/>
    <child link="tool0"/>
    <origin rpy="0 1.5707963267948966 0" xyz="0.075 0 0"/>
    <axis xyz="-1 0 0"/>
  </joint>
  <joint name="tool0-tcp_kuka" type="fixed">
    <parent link="tool0"/>
    <child link="tcp_kuka"/>
    <origin rpy="0 0 0" xyz="0 0.0625 0.19"/>
    <axis xyz="-1 0 0"/>
  </joint>
  <!-- ROS base_link to KUKA $ROBROOT coordinate system transform -->
  <!-- commented below for testing -->
  <!-- <link name="${prefix}base" />
    <joint name="${prefix}base_link-base" type="fixed">
      <origin xyz="0 0 0" rpy="0 0 0"/>
      <parent link="${prefix}base_link"/>
      <child link="${prefix}base"/>
    </joint> -->
  <!-- colours based on RAL values given in "FAQ - Colours of robot and robot
       controller", version "KUKA.Tifs | 2010-01-21 |YM| DefaultColorsRobotAndController.doc",
       downloaded 2015-07-18 from
       http://www.kuka.be/main/cservice/faqs/hardware/DefaultColorsRobotAndController.pdf

       all RAL colours converted using http://www.visual-graphics.de/en/customer-care/ral-colours
  -->
  <link name="telebot_cell_base_link">
    <visual>
      <origin rpy="0 0 0" xyz="0 0 0"/>
      <geometry>
        <mesh filename="package://example-robot-data/robots/dual_robot_description/meshes/visual/telebot_cell.stl" scale="1 1 1"/>
      </geometry>
    </visual>
    <collision>
      <origin rpy="0 0 0" xyz="0.0 0.0 0.0"/>
      <geometry>
        <mesh filename="package://example-robot-data/robots/dual_robot_description/meshes/collision/telebot_cell.stl" scale="1 1 1"/>
      </geometry>
    </collision>
    <!-- <inertial>
                <mass value="1.0"/>
                <origin rpy="0 0 0" xyz="0 0 0.0"/>
                <inertia ixx="1.0" iyy="0.0" izz="0.0"
                    ixy="1.0" ixz="1.0" iyz="1.0"/>
            </inertial> -->
  </link>
  <!-- Positioning the Meca500 -->
  <!-- <xacro:meca_500_r3 prefix="${meca_prefix}"/>
        <joint name="meca_to_table" type="fixed">
            <parent link="telebot_cell_base_link"/>
            <child link="${meca_prefix}meca_base_link"/>
            <origin xyz="0.7 0.2 0.02" rpy="0 0 ${pi/2}"/>
        </joint> -->
  <!-- <link name="telebot_base"/>
        <joint name="tele_cell-tele_base" type="fixed">
            <origin xyz="0 0 0" rpy="0 0 0"/>
            <parent link="telebot_base"/>
            <child link="telebot_cell_base_link"/>
        </joint> -->
  <!-- Define the main robot links and joints -->
  <!-- Define the joint that connects the end effector to the base -->
  <joint name="telebot_cell_base_link_kuka_base_link" type="fixed">
    <parent link="telebot_cell_base_link"/>
    <!-- The base of the robot -->
    <child link="base_link"/>
    <!-- The end effector of the arm -->
    <origin rpy="0 0 -1.5708" xyz="-0.52 -0.2345 -0.291"/>
    <!-- Adjust these values as needed -->
    <axis xyz="0 0 1"/>
    <!-- The axis of rotation (if applicable) -->
  </joint>
  <joint name="meca_to_kuka_joint" type="fixed">
    <parent link="base_link"/>
    <!-- The base of the robot -->
    <child link="meca_base_link"/>
    <!-- The end effector of the arm -->
    <origin xyz="-0.14489 0.50155 0.17690"/>
    <!-- Adjust these values as needed -->
    <axis xyz="0 0 1"/>
    <!-- The axis of rotation (if applicable) -->
  </joint>
</robot>

